<?xml version="1.0" ?>
<robot name="Terrestrial_Robot_Export" xmlns:xacro="http://www.ros.org/wiki/xacro">

<xacro:include filename="$(find Terrestrial_Robot_Export_description)/urdf/materials.xacro" />
<xacro:include filename="$(find Terrestrial_Robot_Export_description)/urdf/Terrestrial_Robot_Export.trans" />
<xacro:include filename="$(find Terrestrial_Robot_Export_description)/urdf/Terrestrial_Robot_Export.gazebo" />
<link name="base_link">
  <!-- <inertial>
    <origin xyz="-5.183336997375715e-17 -0.007592361577329013 0.006868005732278094" rpy="0 0 0"/>
    <mass value="4.133882166278983"/>
    <inertia ixx="0.015635" iyy="0.018694" izz="0.033526" ixy="0.0" iyz="0.000385" ixz="-0.0"/>
  </inertial> -->
  <visual>
    <origin xyz="0 0 0" rpy="0 0 0"/>
    <geometry>
      <mesh filename="file://$(find Terrestrial_Robot_Export_description)/meshes/base_link.stl" scale="0.001 0.001 0.001"/>
    </geometry>
    <material name="silver"/>
  </visual>
  <collision>
    <origin xyz="0 0 0" rpy="0 0 0"/>
    <geometry>
      <mesh filename="file://$(find Terrestrial_Robot_Export_description)/meshes/base_link.stl" scale="0.001 0.001 0.001"/>
    </geometry>
  </collision>
</link>

<link name="MotorModel_BackLeft_1">
  <inertial>
    <origin xyz="0.02871297796531838 -2.7755575615628914e-17 -2.588679252936432e-07" rpy="0 0 0"/>
    <mass value="0.48529585489779975"/>
    <inertia ixx="8e-05" iyy="0.000182" izz="0.000182" ixy="0.0" iyz="-0.0" ixz="-0.0"/>
  </inertial>
  <visual>
    <origin xyz="0.096 0.065 0.0185" rpy="0 0 0"/>
    <geometry>
      <mesh filename="file://$(find Terrestrial_Robot_Export_description)/meshes/MotorModel_BackLeft_1.stl" scale="0.001 0.001 0.001"/>
    </geometry>
    <material name="silver"/>
  </visual>
  <collision>
    <origin xyz="0.096 0.065 0.0185" rpy="0 0 0"/>
    <geometry>
      <mesh filename="file://$(find Terrestrial_Robot_Export_description)/meshes/MotorModel_BackLeft_1.stl" scale="0.001 0.001 0.001"/>
    </geometry>
  </collision>
</link>

<link name="Wheel_BackLeft_1">
  <inertial>
    <origin xyz="-0.022503490882874108 3.597777147909542e-06 5.419452380719253e-06" rpy="0 0 0"/>
    <mass value="2.595058966151119"/>
    <inertia ixx="0.003063" iyy="0.001968" izz="0.001969" ixy="0.0" iyz="-0.0" ixz="0.0"/>
  </inertial>
  <visual>
    <origin xyz="0.102 0.065 0.0185" rpy="0 0 0"/>
    <geometry>
      <mesh filename="file://$(find Terrestrial_Robot_Export_description)/meshes/Wheel_BackLeft_1.stl" scale="0.001 0.001 0.001"/>
    </geometry>
    <material name="silver"/>
  </visual>
  <collision>
    <origin xyz="0.102 0.065 0.0185" rpy="0 0 0"/>
    <geometry>
      <mesh filename="file://$(find Terrestrial_Robot_Export_description)/meshes/Wheel_BackLeft_1.stl" scale="0.001 0.001 0.001"/>
    </geometry>
  </collision>
</link>

<link name="MotorModel_BackRight_1">
  <inertial>
    <origin xyz="-0.028712977965318395 1.3877787807814457e-17 -2.588679252936432e-07" rpy="0 0 0"/>
    <mass value="0.48529585489779975"/>
    <inertia ixx="8e-05" iyy="0.000182" izz="0.000182" ixy="0.0" iyz="0.0" ixz="0.0"/>
  </inertial>
  <visual>
    <origin xyz="-0.096 0.065 0.0185" rpy="0 0 0"/>
    <geometry>
      <mesh filename="file://$(find Terrestrial_Robot_Export_description)/meshes/MotorModel_BackRight_1.stl" scale="0.001 0.001 0.001"/>
    </geometry>
    <material name="silver"/>
  </visual>
  <collision>
    <origin xyz="-0.096 0.065 0.0185" rpy="0 0 0"/>
    <geometry>
      <mesh filename="file://$(find Terrestrial_Robot_Export_description)/meshes/MotorModel_BackRight_1.stl" scale="0.001 0.001 0.001"/>
    </geometry>
  </collision>
</link>

<link name="MotorModel_FrontLeft_1">
  <inertial>
    <origin xyz="0.02871297796531838 2.7755575615628914e-17 -2.588679252936432e-07" rpy="0 0 0"/>
    <mass value="0.48529585489779975"/>
    <inertia ixx="8e-05" iyy="0.000182" izz="0.000182" ixy="-0.0" iyz="0.0" ixz="-0.0"/>
  </inertial>
  <visual>
    <origin xyz="0.096 -0.065 0.0185" rpy="0 0 0"/>
    <geometry>
      <mesh filename="file://$(find Terrestrial_Robot_Export_description)/meshes/MotorModel_FrontLeft_1.stl" scale="0.001 0.001 0.001"/>
    </geometry>
    <material name="silver"/>
  </visual>
  <collision>
    <origin xyz="0.096 -0.065 0.0185" rpy="0 0 0"/>
    <geometry>
      <mesh filename="file://$(find Terrestrial_Robot_Export_description)/meshes/MotorModel_FrontLeft_1.stl" scale="0.001 0.001 0.001"/>
    </geometry>
  </collision>
</link>

<link name="MotorModel_FrontRight_1">
  <inertial>
    <origin xyz="-0.02871297796531845 6.938893903907228e-17 -2.588679252936432e-07" rpy="0 0 0"/>
    <mass value="0.48529585489779975"/>
    <inertia ixx="8e-05" iyy="0.000182" izz="0.000182" ixy="0.0" iyz="0.0" ixz="0.0"/>
  </inertial>
  <visual>
    <origin xyz="-0.096 -0.065 0.0185" rpy="0 0 0"/>
    <geometry>
      <mesh filename="file://$(find Terrestrial_Robot_Export_description)/meshes/MotorModel_FrontRight_1.stl" scale="0.001 0.001 0.001"/>
    </geometry>
    <material name="silver"/>
  </visual>
  <collision>
    <origin xyz="-0.096 -0.065 0.0185" rpy="0 0 0"/>
    <geometry>
      <mesh filename="file://$(find Terrestrial_Robot_Export_description)/meshes/MotorModel_FrontRight_1.stl" scale="0.001 0.001 0.001"/>
    </geometry>
  </collision>
</link>

<link name="Wheel_BackRight_1">
  <inertial>
    <origin xyz="0.022503490882874094 -3.5977771478956644e-06 5.419452380712314e-06" rpy="0 0 0"/>
    <mass value="2.595058966151119"/>
    <inertia ixx="0.003063" iyy="0.001968" izz="0.001969" ixy="0.0" iyz="0.0" ixz="-0.0"/>
  </inertial>
  <visual>
    <origin xyz="-0.102 0.065 0.0185" rpy="0 0 0"/>
    <geometry>
      <mesh filename="file://$(find Terrestrial_Robot_Export_description)/meshes/Wheel_BackRight_1.stl" scale="0.001 0.001 0.001"/>
    </geometry>
    <material name="silver"/>
  </visual>
  <collision>
    <origin xyz="-0.102 0.065 0.0185" rpy="0 0 0"/>
    <geometry>
      <mesh filename="file://$(find Terrestrial_Robot_Export_description)/meshes/Wheel_BackRight_1.stl" scale="0.001 0.001 0.001"/>
    </geometry>
  </collision>
</link>

<link name="Wheel_FrontRight_1">
  <inertial>
    <origin xyz="0.022503490882874108 -3.597777147854031e-06 5.419452380712314e-06" rpy="0 0 0"/>
    <mass value="2.595058966151119"/>
    <inertia ixx="0.003063" iyy="0.001968" izz="0.001969" ixy="0.0" iyz="0.0" ixz="-0.0"/>
  </inertial>
  <visual>
    <origin xyz="-0.102 -0.065 0.0185" rpy="0 0 0"/>
    <geometry>
      <mesh filename="file://$(find Terrestrial_Robot_Export_description)/meshes/Wheel_FrontRight_1.stl" scale="0.001 0.001 0.001"/>
    </geometry>
    <material name="silver"/>
  </visual>
  <collision>
    <origin xyz="-0.102 -0.065 0.0185" rpy="0 0 0"/>
    <geometry>
      <mesh filename="file://$(find Terrestrial_Robot_Export_description)/meshes/Wheel_FrontRight_1.stl" scale="0.001 0.001 0.001"/>
    </geometry>
  </collision>
</link>

<link name="Wheel_FrontLeft_1">
  <inertial>
    <origin xyz="-0.022503490882874094 3.5977771478956644e-06 5.419452380719253e-06" rpy="0 0 0"/>
    <mass value="2.595058966151119"/>
    <inertia ixx="0.003063" iyy="0.001968" izz="0.001969" ixy="0.0" iyz="-0.0" ixz="0.0"/>
  </inertial>
  <visual>
    <origin xyz="0.102 -0.065 0.0185" rpy="0 0 0"/>
    <geometry>
      <mesh filename="file://$(find Terrestrial_Robot_Export_description)/meshes/Wheel_FrontLeft_1.stl" scale="0.001 0.001 0.001"/>
    </geometry>
    <material name="silver"/>
  </visual>
  <collision>
    <origin xyz="0.102 -0.065 0.0185" rpy="0 0 0"/>
    <geometry>
      <mesh filename="file://$(find Terrestrial_Robot_Export_description)/meshes/Wheel_FrontLeft_1.stl" scale="0.001 0.001 0.001"/>
    </geometry>
  </collision>
</link>

<joint name="Rigid 26" type="fixed">
  <origin xyz="-0.096 -0.065 -0.0185" rpy="0 0 0"/>
  <parent link="base_link"/>
  <child link="MotorModel_BackLeft_1"/>
</joint>

<joint name="Rigid 28" type="fixed">
  <origin xyz="0.096 -0.065 -0.0185" rpy="0 0 0"/>
  <parent link="base_link"/>
  <child link="MotorModel_BackRight_1"/>
</joint>

<joint name="Rigid 29" type="fixed">
  <origin xyz="-0.096 0.065 -0.0185" rpy="0 0 0"/>
  <parent link="base_link"/>
  <child link="MotorModel_FrontLeft_1"/>
</joint>

<joint name="Rigid 30" type="fixed">
  <origin xyz="0.096 0.065 -0.0185" rpy="0 0 0"/>
  <parent link="base_link"/>
  <child link="MotorModel_FrontRight_1"/>
</joint>

<joint name="Joint_BackLeft" type="continuous">
  <origin xyz="-0.006 0.0 0.0" rpy="0 0 0"/>
  <parent link="MotorModel_BackLeft_1"/>
  <child link="Wheel_BackLeft_1"/>
  <axis xyz="1.0 0.0 0.0"/>
</joint>

<joint name="Joint_BackRight" type="continuous">
  <origin xyz="0.006 0.0 0.0" rpy="0 0 0"/>
  <parent link="MotorModel_BackRight_1"/>
  <child link="Wheel_BackRight_1"/>
  <axis xyz="-1.0 0.0 0.0"/>
</joint>

<joint name="Joint_FrontRight" type="continuous">
  <origin xyz="0.006 0.0 0.0" rpy="0 0 0"/>
  <parent link="MotorModel_FrontRight_1"/>
  <child link="Wheel_FrontRight_1"/>
  <axis xyz="-1.0 0.0 -0.0"/>
</joint>

<joint name="Joint_FrontLeft" type="continuous">
  <origin xyz="-0.006 0.0 0.0" rpy="0 0 0"/>
  <parent link="MotorModel_FrontLeft_1"/>
  <child link="Wheel_FrontLeft_1"/>
  <axis xyz="1.0 0.0 0.0"/>
</joint>

</robot>
